<?xml version="1.0" ?><!-- =================================================================================== --><!-- |    This document was autogenerated by xacro from /tmp/tmpg71efbfn.urdf.xacro    | --><!-- |    EDITING THIS FILE BY HAND IS NOT RECOMMENDED                                 | --><!-- =================================================================================== --><robot name="hand_generated"><link name="hx5_d20_left_base"><visual><origin rpy="0 0 0" xyz="0 0 0"/><geometry><mesh filename="package://robotis_hand_description/meshes/hx5_d20_rev2/hx5_d20_left//hx5_d20_base_unit.stl" scale="0.001 0.001 0.001"/></geometry><material name="grey"><color rgba="0.2 0.2 0.2 1"/></material></visual><collision><origin rpy="0 0 0" xyz="0 0 0"/><geometry><mesh filename="package://robotis_hand_description/meshes/hx5_d20_rev2/hx5_d20_left//hx5_d20_base_unit.stl" scale="0.001 0.001 0.001"/></geometry><material name="grey"><color rgba="0.2 0.2 0.2 1"/></material></collision><inertial><origin xyz="-2.6226269e-03 -1.6836251e-03 6.2283668e-02"/><mass value="3.0185182e-01"/><inertia ixx="5.2854441e-04" ixy="-9.4576969e-06" ixz="-1.8870822e-06" iyy="3.8232027e-04" iyz="-3.4927346e-07" izz="2.0124950e-04"/></inertial></link><!-- THUMB --><joint name="finger_l_joint1" type="revolute"><parent link="hx5_d20_left_base"/><child link="finger_l_link1"/><origin rpy="0 0 0" xyz="-0.0125 -0.03493 0.04475"/><axis xyz="1 0 0"/><limit effort="1000" lower="-1.57" upper="1.57" velocity="4.8"/><dynamics damping="0.05"/></joint><link name="finger_l_link1"><visual><origin rpy="0 0 0" xyz="0 0 0"/><geometry><mesh filename="package://robotis_hand_description/meshes/hx5_d20_rev2/hx5_d20_left//hx5_d20_thumb_mcp.stl" scale="0.001 0.001 0.001"/></geometry><material name="grey"><color rgba="0.2 0.2 0.2 1"/></material></visual><collision><origin rpy="0 0 0" xyz="0 0 0"/><geometry><mesh filename="package://robotis_hand_description/meshes/hx5_d20_rev2/hx5_d20_left//hx5_d20_thumb_mcp.stl" scale="0.001 0.001 0.001"/></geometry><material name="grey"><color rgba="0.2 0.2 0.2 1"/></material></collision><inertial><origin xyz="2.3807543e-02 -1.3864423e-03 -1.7245618e-05"/><mass value="4.0868482e-02"/><inertia ixx="2.8827174e-06" ixy="-1.2704973e-06" ixz="1.6732651e-08" iyy="9.3996806e-06" iyz="1.5043128e-09" izz="9.6857093e-06"/></inertial></link><joint name="finger_l_joint2" type="revolute"><parent link="finger_l_link1"/><child link="finger_l_link2"/><origin rpy="0 0 0" xyz="0.039 0.0 0.0"/><axis xyz="0 0 1"/><limit effort="1000" lower="0.0" upper="3.14" velocity="4.8"/><dynamics damping="0.05"/></joint><link name="finger_l_link2"><visual><origin rpy="0 0 0" xyz="0 0 0"/><geometry><mesh filename="package://robotis_hand_description/meshes/hx5_d20_rev2/hx5_d20_left//hx5_d20_thumb_mcp2.stl" scale="0.001 0.001 0.001"/></geometry><material name="grey"><color rgba="0.2 0.2 0.2 1"/></material></visual><collision><origin rpy="0 0 0" xyz="0 0 0"/><geometry><mesh filename="package://robotis_hand_description/meshes/hx5_d20_rev2/hx5_d20_left//hx5_d20_thumb_mcp2.stl" scale="0.001 0.001 0.001"/></geometry><material name="grey"><color rgba="0.2 0.2 0.2 1"/></material></collision><inertial><origin xyz="3.5667920e-04 -1.3999343e-02 3.5920711e-04"/><mass value="1.1760611e-02"/><inertia ixx="1.3023455e-06" ixy="5.3492870e-08" ixz="1.5067505e-09" iyy="1.0556381e-06" iyz="-5.3427868e-08" izz="1.3024709e-06"/></inertial></link><joint name="finger_l_joint3" type="revolute"><parent link="finger_l_link2"/><child link="finger_l_link3"/><origin rpy="0 0 0" xyz="0.0 -0.028 0.0"/><axis xyz="1 0 0"/><limit effort="1000" lower="-1.57" upper="0.0" velocity="4.8"/><dynamics damping="0.05"/></joint><link name="finger_l_link3"><visual><origin rpy="0 0 0" xyz="0 0 0"/><geometry><mesh filename="package://robotis_hand_description/meshes/hx5_d20_rev2/hx5_d20_left//hx5_d20_thumb_ip.stl" scale="0.001 0.001 0.001"/></geometry><material name="grey"><color rgba="0.2 0.2 0.2 1"/></material></visual><collision><origin rpy="0 0 0" xyz="0 0 0"/><geometry><mesh filename="package://robotis_hand_description/meshes/hx5_d20_rev2/hx5_d20_left//hx5_d20_thumb_ip.stl" scale="0.001 0.001 0.001"/></geometry><material name="grey"><color rgba="0.2 0.2 0.2 1"/></material></collision><inertial><origin xyz="1.0146203e-04 -1.1343515e-02 4.0805550e-06"/><mass value="3.4689700e-02"/><inertia ixx="5.0370173e-06" ixy="1.1035638e-07" ixz="5.4161055e-10" iyy="2.2580703e-06" iyz="-8.5483839e-10" izz="5.4029785e-06"/></inertial></link><joint name="finger_l_joint4" type="revolute"><parent link="finger_l_link3"/><child link="finger_l_link4"/><origin rpy="0 0 0" xyz="0.0 -0.0355 0.0"/><axis xyz="1 0 0"/><limit effort="1000" lower="-1.57" upper="0.0" velocity="4.8"/><dynamics damping="0.05"/></joint><link name="finger_l_link4"><visual><origin rpy="0 0 0" xyz="0 0 0"/><geometry><mesh filename="package://robotis_hand_description/meshes/hx5_d20_rev2/hx5_d20_left//hx5_d20_thumb_tip.stl" scale="0.001 0.001 0.001"/></geometry><material name="grey"><color rgba="0.2 0.2 0.2 1"/></material></visual><collision><origin rpy="0 0 0" xyz="0 0 0"/><geometry><mesh filename="package://robotis_hand_description/meshes/hx5_d20_rev2/hx5_d20_left//hx5_d20_thumb_tip.stl" scale="0.001 0.001 0.001"/></geometry><material name="grey"><color rgba="0.2 0.2 0.2 1"/></material></collision><inertial><origin xyz="-1.7938916e-05 -1.6839136e-02 2.3602399e-04"/><mass value="4.3781048e-02"/><inertia ixx="1.1225495e-05" ixy="1.5543842e-08" ixz="5.8360810e-10" iyy="2.7956646e-06" iyz="3.1575945e-07" izz="1.1392997e-05"/></inertial></link><joint name="finger_end_l_joint1" type="fixed"><parent link="finger_l_link4"/><child link="finger_end_l_link1"/><origin rpy="0 0 0" xyz="0.0 -0.03975 0.0"/></joint><link name="finger_end_l_link1"><visual><origin rpy="0 0 0" xyz="0 0 0"/><geometry><box size="0.01 0.01 0.01"/></geometry><material name="red"><color rgba="1.0 0.0 0.0 1"/></material></visual></link><!-- INDEX --><joint name="finger_l_joint5" type="revolute"><parent link="hx5_d20_left_base"/><child link="finger_l_link5"/><origin rpy="0 0 0" xyz="-0.0015 -0.03608 0.10275"/><axis xyz="1 0 0"/><limit effort="1000" lower="-0.6" upper="0.6" velocity="4.8"/><dynamics damping="0.05"/></joint><link name="finger_l_link5"><visual><origin rpy="0 0 0" xyz="0 0 0"/><geometry><mesh filename="package://robotis_hand_description/meshes/hx5_d20_rev2/hx5_d20_left//hx5_d20_finger_mcp.stl" scale="0.001 0.001 0.001"/></geometry><material name="grey"><color rgba="0.2 0.2 0.2 1"/></material></visual><collision><origin rpy="0 0 0" xyz="0 0 0"/><geometry><mesh filename="package://robotis_hand_description/meshes/hx5_d20_rev2/hx5_d20_left//hx5_d20_finger_mcp.stl" scale="0.001 0.001 0.001"/></geometry><material name="grey"><color rgba="0.2 0.2 0.2 1"/></material></collision><inertial><origin xyz="5.193401000e-03 -1.816308100e-05 2.111550700e-02"/><mass value="3.880441100e-02"/><inertia ixx="3.524993200e-06" ixy="1.364133900e-08" ixz="-3.766210300e-07" iyy="5.792157500e-06" iyz="1.153419900e-09" izz="4.712679800e-06"/></inertial></link><joint name="finger_l_joint6" type="revolute"><parent link="finger_l_link5"/><child link="finger_l_link6"/><origin rpy="0 0 0" xyz="0.0165 0.0 0.0235"/><axis xyz="0 1 0"/><limit effort="1000" lower="0.0" upper="2.0" velocity="4.8"/><dynamics damping="0.05"/></joint><link name="finger_l_link6"><visual><origin rpy="0 0 0" xyz="0 0 0"/><geometry><mesh filename="package://robotis_hand_description/meshes/hx5_d20_rev2/hx5_d20_left//hx5_d20_finger_pip.stl" scale="0.001 0.001 0.001"/></geometry><material name="grey"><color rgba="0.2 0.2 0.2 1"/></material></visual><collision><origin rpy="0 0 0" xyz="0 0 0"/><geometry><mesh filename="package://robotis_hand_description/meshes/hx5_d20_rev2/hx5_d20_left//hx5_d20_finger_pip.stl" scale="0.001 0.001 0.001"/></geometry><material name="grey"><color rgba="0.2 0.2 0.2 1"/></material></collision><inertial><origin xyz="4.080555000e-06 1.014620300e-04 2.415648500e-02"/><mass value="3.468970000e-02"/><inertia ixx="5.402978500e-06" ixy="5.416105500e-10" ixz="-8.548383300e-10" iyy="5.037017300e-06" iyz="1.103563800e-07" izz="2.258070300e-06"/></inertial></link><joint name="finger_l_joint7" type="revolute"><parent link="finger_l_link6"/><child link="finger_l_link7"/><origin rpy="0 0 0" xyz="0.0 0.0 0.0355"/><axis xyz="0 1 0"/><limit effort="1000" lower="0.0" upper="1.57" velocity="4.8"/><dynamics damping="0.05"/></joint><link name="finger_l_link7"><visual><origin rpy="0 0 0" xyz="0 0 0"/><geometry><mesh filename="package://robotis_hand_description/meshes/hx5_d20_rev2/hx5_d20_left//hx5_d20_finger_dip.stl" scale="0.001 0.001 0.001"/></geometry><material name="grey"><color rgba="0.2 0.2 0.2 1"/></material></visual><collision><origin rpy="0 0 0" xyz="0 0 0"/><geometry><mesh filename="package://robotis_hand_description/meshes/hx5_d20_rev2/hx5_d20_left//hx5_d20_finger_dip.stl" scale="0.001 0.001 0.001"/></geometry><material name="grey"><color rgba="0.2 0.2 0.2 1"/></material></collision><inertial><origin xyz="4.080555000e-06 1.014620300e-04 2.415648500e-02"/><mass value="3.468970000e-02"/><inertia ixx="5.402978500e-06" ixy="5.416105500e-10" ixz="-8.548383900e-10" iyy="5.037017300e-06" iyz="1.103563800e-07" izz="2.258070300e-06"/></inertial></link><joint name="finger_l_joint8" type="revolute"><parent link="finger_l_link7"/><child link="finger_l_link8"/><origin rpy="0 0 0" xyz="0.0 0.0 0.0355"/><axis xyz="0 1 0"/><limit effort="1000" lower="0.0" upper="1.57" velocity="4.8"/><dynamics damping="0.05"/></joint><link name="finger_l_link8"><visual><origin rpy="0 0 0" xyz="0 0 0"/><geometry><mesh filename="package://robotis_hand_description/meshes/hx5_d20_rev2/hx5_d20_left//hx5_d20_finger_tip.stl" scale="0.001 0.001 0.001"/></geometry><material name="grey"><color rgba="0.2 0.2 0.2 1"/></material></visual><collision><origin rpy="0 0 0" xyz="0 0 0"/><geometry><mesh filename="package://robotis_hand_description/meshes/hx5_d20_rev2/hx5_d20_left//hx5_d20_finger_tip.stl" scale="0.001 0.001 0.001"/></geometry><material name="grey"><color rgba="0.2 0.2 0.2 1"/></material></collision><inertial><origin xyz="7.102508500e-04 4.723840800e-04 1.809864000e-02"/><mass value="1.363720100e-02"/><inertia ixx="2.232432600e-06" ixy="2.731013800e-09" ixz="-1.436237900e-07" iyy="2.018806500e-06" iyz="8.149987600e-08" izz="1.078660600e-06"/></inertial></link><joint name="finger_end_l_joint2" type="fixed"><parent link="finger_l_link8"/><child link="finger_end_l_link2"/><origin rpy="0 0 0" xyz="0.0 0.0 0.02425"/></joint><link name="finger_end_l_link2"><visual><origin rpy="0 0 0" xyz="0 0 0"/><geometry><box size="0.01 0.01 0.01"/></geometry><material name="red"><color rgba="1.0 0.0 0.0 1"/></material></visual></link><!-- MIDDLE --><joint name="finger_l_joint9" type="revolute"><parent link="hx5_d20_left_base"/><child link="finger_l_link9"/><origin rpy="0 0 0" xyz="-0.0015 -0.00908 0.11053"/><axis xyz="1 0 0"/><limit effort="1000" lower="-0.6" upper="0.6" velocity="4.8"/><dynamics damping="0.05"/></joint><link name="finger_l_link9"><visual><origin rpy="0 0 0" xyz="0 0 0"/><geometry><mesh filename="package://robotis_hand_description/meshes/hx5_d20_rev2/hx5_d20_left//hx5_d20_finger_mcp.stl" scale="0.001 0.001 0.001"/></geometry><material name="grey"><color rgba="0.2 0.2 0.2 1"/></material></visual><collision><origin rpy="0 0 0" xyz="0 0 0"/><geometry><mesh filename="package://robotis_hand_description/meshes/hx5_d20_rev2/hx5_d20_left//hx5_d20_finger_mcp.stl" scale="0.001 0.001 0.001"/></geometry><material name="grey"><color rgba="0.2 0.2 0.2 1"/></material></collision><inertial><origin xyz="5.193401000e-03 -1.816308100e-05 2.111550700e-02"/><mass value="3.880441100e-02"/><inertia ixx="3.524993200e-06" ixy="1.364133900e-08" ixz="-3.766210300e-07" iyy="5.792157500e-06" iyz="1.153419900e-09" izz="4.712679800e-06"/></inertial></link><joint name="finger_l_joint10" type="revolute"><parent link="finger_l_link9"/><child link="finger_l_link10"/><origin rpy="0 0 0" xyz="0.0165 0.0 0.0235"/><axis xyz="0 1 0"/><limit effort="1000" lower="0.0" upper="2.0" velocity="4.8"/><dynamics damping="0.05"/></joint><link name="finger_l_link10"><visual><origin rpy="0 0 0" xyz="0 0 0"/><geometry><mesh filename="package://robotis_hand_description/meshes/hx5_d20_rev2/hx5_d20_left//hx5_d20_finger_pip.stl" scale="0.001 0.001 0.001"/></geometry><material name="grey"><color rgba="0.2 0.2 0.2 1"/></material></visual><collision><origin rpy="0 0 0" xyz="0 0 0"/><geometry><mesh filename="package://robotis_hand_description/meshes/hx5_d20_rev2/hx5_d20_left//hx5_d20_finger_pip.stl" scale="0.001 0.001 0.001"/></geometry><material name="grey"><color rgba="0.2 0.2 0.2 1"/></material></collision><inertial><origin xyz="4.080555000e-06 1.014620300e-04 2.415648500e-02"/><mass value="3.468970000e-02"/><inertia ixx="5.402978500e-06" ixy="5.416105500e-10" ixz="-8.548383300e-10" iyy="5.037017300e-06" iyz="1.103563800e-07" izz="2.258070300e-06"/></inertial></link><joint name="finger_l_joint11" type="revolute"><parent link="finger_l_link10"/><child link="finger_l_link11"/><origin rpy="0 0 0" xyz="0.0 0.0 0.0355"/><axis xyz="0 1 0"/><limit effort="1000" lower="0.0" upper="1.57" velocity="4.8"/><dynamics damping="0.05"/></joint><link name="finger_l_link11"><visual><origin rpy="0 0 0" xyz="0 0 0"/><geometry><mesh filename="package://robotis_hand_description/meshes/hx5_d20_rev2/hx5_d20_left//hx5_d20_finger_dip.stl" scale="0.001 0.001 0.001"/></geometry><material name="grey"><color rgba="0.2 0.2 0.2 1"/></material></visual><collision><origin rpy="0 0 0" xyz="0 0 0"/><geometry><mesh filename="package://robotis_hand_description/meshes/hx5_d20_rev2/hx5_d20_left//hx5_d20_finger_dip.stl" scale="0.001 0.001 0.001"/></geometry><material name="grey"><color rgba="0.2 0.2 0.2 1"/></material></collision><inertial><origin xyz="4.080555000e-06 1.014620300e-04 2.415648500e-02"/><mass value="3.468970000e-02"/><inertia ixx="5.402978500e-06" ixy="5.416105500e-10" ixz="-8.548383900e-10" iyy="5.037017300e-06" iyz="1.103563800e-07" izz="2.258070300e-06"/></inertial></link><joint name="finger_l_joint12" type="revolute"><parent link="finger_l_link11"/><child link="finger_l_link12"/><origin rpy="0 0 0" xyz="0.0 0.0 0.0355"/><axis xyz="0 1 0"/><limit effort="1000" lower="0.0" upper="1.57" velocity="4.8"/><dynamics damping="0.05"/></joint><link name="finger_l_link12"><visual><origin rpy="0 0 0" xyz="0 0 0"/><geometry><mesh filename="package://robotis_hand_description/meshes/hx5_d20_rev2/hx5_d20_left//hx5_d20_finger_tip.stl" scale="0.001 0.001 0.001"/></geometry><material name="grey"><color rgba="0.2 0.2 0.2 1"/></material></visual><collision><origin rpy="0 0 0" xyz="0 0 0"/><geometry><mesh filename="package://robotis_hand_description/meshes/hx5_d20_rev2/hx5_d20_left//hx5_d20_finger_tip.stl" scale="0.001 0.001 0.001"/></geometry><material name="grey"><color rgba="0.2 0.2 0.2 1"/></material></collision><inertial><origin xyz="7.102508500e-04 4.723840800e-04 1.809864000e-02"/><mass value="1.363720100e-02"/><inertia ixx="2.232432600e-06" ixy="2.731013800e-09" ixz="-1.436237900e-07" iyy="2.018806500e-06" iyz="8.149987600e-08" izz="1.078660600e-06"/></inertial></link><joint name="finger_end_l_joint3" type="fixed"><parent link="finger_l_link12"/><child link="finger_end_l_link3"/><origin rpy="0 0 0" xyz="0.0 0.0 0.02425"/></joint><link name="finger_end_l_link3"><visual><origin rpy="0 0 0" xyz="0 0 0"/><geometry><box size="0.01 0.01 0.01"/></geometry><material name="red"><color rgba="1.0 0.0 0.0 1"/></material></visual></link><!-- RING --><joint name="finger_l_joint13" type="revolute"><parent link="hx5_d20_left_base"/><child link="finger_l_link13"/><origin rpy="0 0 0" xyz="-0.0015 0.01792 0.10475"/><axis xyz="1 0 0"/><limit effort="1000" lower="-0.6" upper="0.6" velocity="4.8"/><dynamics damping="0.05"/></joint><link name="finger_l_link13"><visual><origin rpy="0 0 0" xyz="0 0 0"/><geometry><mesh filename="package://robotis_hand_description/meshes/hx5_d20_rev2/hx5_d20_left//hx5_d20_finger_mcp.stl" scale="0.001 0.001 0.001"/></geometry><material name="grey"><color rgba="0.2 0.2 0.2 1"/></material></visual><collision><origin rpy="0 0 0" xyz="0 0 0"/><geometry><mesh filename="package://robotis_hand_description/meshes/hx5_d20_rev2/hx5_d20_left//hx5_d20_finger_mcp.stl" scale="0.001 0.001 0.001"/></geometry><material name="grey"><color rgba="0.2 0.2 0.2 1"/></material></collision><inertial><origin xyz="5.193401000e-03 -1.816308100e-05 2.111550700e-02"/><mass value="3.880441100e-02"/><inertia ixx="3.524993200e-06" ixy="1.364133900e-08" ixz="-3.766210300e-07" iyy="5.792157500e-06" iyz="1.153419900e-09" izz="4.712679800e-06"/></inertial></link><joint name="finger_l_joint14" type="revolute"><parent link="finger_l_link13"/><child link="finger_l_link14"/><origin rpy="0 0 0" xyz="0.0165 0.0 0.0235"/><axis xyz="0 1 0"/><limit effort="1000" lower="0.0" upper="2.0" velocity="4.8"/><dynamics damping="0.05"/></joint><link name="finger_l_link14"><visual><origin rpy="0 0 0" xyz="0 0 0"/><geometry><mesh filename="package://robotis_hand_description/meshes/hx5_d20_rev2/hx5_d20_left//hx5_d20_finger_pip.stl" scale="0.001 0.001 0.001"/></geometry><material name="grey"><color rgba="0.2 0.2 0.2 1"/></material></visual><collision><origin rpy="0 0 0" xyz="0 0 0"/><geometry><mesh filename="package://robotis_hand_description/meshes/hx5_d20_rev2/hx5_d20_left//hx5_d20_finger_pip.stl" scale="0.001 0.001 0.001"/></geometry><material name="grey"><color rgba="0.2 0.2 0.2 1"/></material></collision><inertial><origin xyz="4.080555000e-06 1.014620300e-04 2.415648500e-02"/><mass value="3.468970000e-02"/><inertia ixx="5.402978500e-06" ixy="5.416105500e-10" ixz="-8.548383300e-10" iyy="5.037017300e-06" iyz="1.103563800e-07" izz="2.258070300e-06"/></inertial></link><joint name="finger_l_joint15" type="revolute"><parent link="finger_l_link14"/><child link="finger_l_link15"/><origin rpy="0 0 0" xyz="0.0 0.0 0.0355"/><axis xyz="0 1 0"/><limit effort="1000" lower="0.0" upper="1.57" velocity="4.8"/><dynamics damping="0.05"/></joint><link name="finger_l_link15"><visual><origin rpy="0 0 0" xyz="0 0 0"/><geometry><mesh filename="package://robotis_hand_description/meshes/hx5_d20_rev2/hx5_d20_left//hx5_d20_finger_dip.stl" scale="0.001 0.001 0.001"/></geometry><material name="grey"><color rgba="0.2 0.2 0.2 1"/></material></visual><collision><origin rpy="0 0 0" xyz="0 0 0"/><geometry><mesh filename="package://robotis_hand_description/meshes/hx5_d20_rev2/hx5_d20_left//hx5_d20_finger_dip.stl" scale="0.001 0.001 0.001"/></geometry><material name="grey"><color rgba="0.2 0.2 0.2 1"/></material></collision><inertial><origin xyz="4.080555000e-06 1.014620300e-04 2.415648500e-02"/><mass value="3.468970000e-02"/><inertia ixx="5.402978500e-06" ixy="5.416105500e-10" ixz="-8.548383900e-10" iyy="5.037017300e-06" iyz="1.103563800e-07" izz="2.258070300e-06"/></inertial></link><joint name="finger_l_joint16" type="revolute"><parent link="finger_l_link15"/><child link="finger_l_link16"/><origin rpy="0 0 0" xyz="0.0 0.0 0.0355"/><axis xyz="0 1 0"/><limit effort="1000" lower="0.0" upper="1.57" velocity="4.8"/><dynamics damping="0.05"/></joint><link name="finger_l_link16"><visual><origin rpy="0 0 0" xyz="0 0 0"/><geometry><mesh filename="package://robotis_hand_description/meshes/hx5_d20_rev2/hx5_d20_left//hx5_d20_finger_tip.stl" scale="0.001 0.001 0.001"/></geometry><material name="grey"><color rgba="0.2 0.2 0.2 1"/></material></visual><collision><origin rpy="0 0 0" xyz="0 0 0"/><geometry><mesh filename="package://robotis_hand_description/meshes/hx5_d20_rev2/hx5_d20_left//hx5_d20_finger_tip.stl" scale="0.001 0.001 0.001"/></geometry><material name="grey"><color rgba="0.2 0.2 0.2 1"/></material></collision><inertial><origin xyz="7.102508500e-04 4.723840800e-04 1.809864000e-02"/><mass value="1.363720100e-02"/><inertia ixx="2.232432600e-06" ixy="2.731013800e-09" ixz="-1.436237900e-07" iyy="2.018806500e-06" iyz="8.149987600e-08" izz="1.078660600e-06"/></inertial></link><joint name="finger_end_l_joint4" type="fixed"><parent link="finger_l_link16"/><child link="finger_end_l_link4"/><origin rpy="0 0 0" xyz="0.0 0.0 0.02425"/></joint><link name="finger_end_l_link4"><visual><origin rpy="0 0 0" xyz="0 0 0"/><geometry><box size="0.01 0.01 0.01"/></geometry><material name="red"><color rgba="1.0 0.0 0.0 1"/></material></visual></link><!-- PINKY --><joint name="finger_l_joint17" type="revolute"><parent link="hx5_d20_left_base"/><child link="finger_l_link17"/><origin rpy="0 0 0" xyz="-0.0015 0.04492 0.08575"/><axis xyz="1 0 0"/><limit effort="1000" lower="-0.6" upper="0.6" velocity="4.8"/><dynamics damping="0.05"/></joint><link name="finger_l_link17"><visual><origin rpy="0 0 0" xyz="0 0 0"/><geometry><mesh filename="package://robotis_hand_description/meshes/hx5_d20_rev2/hx5_d20_left//hx5_d20_finger_mcp.stl" scale="0.001 0.001 0.001"/></geometry><material name="grey"><color rgba="0.2 0.2 0.2 1"/></material></visual><collision><origin rpy="0 0 0" xyz="0 0 0"/><geometry><mesh filename="package://robotis_hand_description/meshes/hx5_d20_rev2/hx5_d20_left//hx5_d20_finger_mcp.stl" scale="0.001 0.001 0.001"/></geometry><material name="grey"><color rgba="0.2 0.2 0.2 1"/></material></collision><inertial><origin xyz="5.193401000e-03 -1.816308100e-05 2.111550700e-02"/><mass value="3.880441100e-02"/><inertia ixx="3.524993200e-06" ixy="1.364133900e-08" ixz="-3.766210300e-07" iyy="5.792157500e-06" iyz="1.153419900e-09" izz="4.712679800e-06"/></inertial></link><joint name="finger_l_joint18" type="revolute"><parent link="finger_l_link17"/><child link="finger_l_link18"/><origin rpy="0 0 0" xyz="0.0165 0.0 0.0235"/><axis xyz="0 1 0"/><limit effort="1000" lower="0.0" upper="2.0" velocity="4.8"/><dynamics damping="0.05"/></joint><link name="finger_l_link18"><visual><origin rpy="0 0 0" xyz="0 0 0"/><geometry><mesh filename="package://robotis_hand_description/meshes/hx5_d20_rev2/hx5_d20_left//hx5_d20_finger_pip.stl" scale="0.001 0.001 0.001"/></geometry><material name="grey"><color rgba="0.2 0.2 0.2 1"/></material></visual><collision><origin rpy="0 0 0" xyz="0 0 0"/><geometry><mesh filename="package://robotis_hand_description/meshes/hx5_d20_rev2/hx5_d20_left//hx5_d20_finger_pip.stl" scale="0.001 0.001 0.001"/></geometry><material name="grey"><color rgba="0.2 0.2 0.2 1"/></material></collision><inertial><origin xyz="4.080555000e-06 1.014620300e-04 2.415648500e-02"/><mass value="3.468970000e-02"/><inertia ixx="5.402978500e-06" ixy="5.416105500e-10" ixz="-8.548383300e-10" iyy="5.037017300e-06" iyz="1.103563800e-07" izz="2.258070300e-06"/></inertial></link><joint name="finger_l_joint19" type="revolute"><parent link="finger_l_link18"/><child link="finger_l_link19"/><origin rpy="0 0 0" xyz="0.0 0.0 0.0355"/><axis xyz="0 1 0"/><limit effort="1000" lower="0.0" upper="1.57" velocity="4.8"/><dynamics damping="0.05"/></joint><link name="finger_l_link19"><visual><origin rpy="0 0 0" xyz="0 0 0"/><geometry><mesh filename="package://robotis_hand_description/meshes/hx5_d20_rev2/hx5_d20_left//hx5_d20_finger_dip.stl" scale="0.001 0.001 0.001"/></geometry><material name="grey"><color rgba="0.2 0.2 0.2 1"/></material></visual><collision><origin rpy="0 0 0" xyz="0 0 0"/><geometry><mesh filename="package://robotis_hand_description/meshes/hx5_d20_rev2/hx5_d20_left//hx5_d20_finger_dip.stl" scale="0.001 0.001 0.001"/></geometry><material name="grey"><color rgba="0.2 0.2 0.2 1"/></material></collision><inertial><origin xyz="4.080555000e-06 1.014620300e-04 2.415648500e-02"/><mass value="3.468970000e-02"/><inertia ixx="5.402978500e-06" ixy="5.416105500e-10" ixz="-8.548383900e-10" iyy="5.037017300e-06" iyz="1.103563800e-07" izz="2.258070300e-06"/></inertial></link><joint name="finger_l_joint20" type="revolute"><parent link="finger_l_link19"/><child link="finger_l_link20"/><origin rpy="0 0 0" xyz="0.0 0.0 0.0355"/><axis xyz="0 1 0"/><limit effort="1000" lower="0.0" upper="1.57" velocity="4.8"/><dynamics damping="0.05"/></joint><link name="finger_l_link20"><visual><origin rpy="0 0 0" xyz="0 0 0"/><geometry><mesh filename="package://robotis_hand_description/meshes/hx5_d20_rev2/hx5_d20_left//hx5_d20_finger_tip.stl" scale="0.001 0.001 0.001"/></geometry><material name="grey"><color rgba="0.2 0.2 0.2 1"/></material></visual><collision><origin rpy="0 0 0" xyz="0 0 0"/><geometry><mesh filename="package://robotis_hand_description/meshes/hx5_d20_rev2/hx5_d20_left//hx5_d20_finger_tip.stl" scale="0.001 0.001 0.001"/></geometry><material name="grey"><color rgba="0.2 0.2 0.2 1"/></material></collision><inertial><origin xyz="7.102508500e-04 4.723840800e-04 1.809864000e-02"/><mass value="1.363720100e-02"/><inertia ixx="2.232432600e-06" ixy="2.731013800e-09" ixz="-1.436237900e-07" iyy="2.018806500e-06" iyz="8.149987600e-08" izz="1.078660600e-06"/></inertial></link><joint name="finger_end_l_joint5" type="fixed"><parent link="finger_l_link20"/><child link="finger_end_l_link5"/><origin rpy="0 0 0" xyz="0.0 0.0 0.02425"/></joint><link name="finger_end_l_link5"><visual><origin rpy="0 0 0" xyz="0 0 0"/><geometry><box size="0.01 0.01 0.01"/></geometry><material name="red"><color rgba="1.0 0.0 0.0 1"/></material></visual></link></robot>